-- mods/australia/biome_far_north_queensland.lua

local biome_name = "far_north_queensland"
local node_top = "default:dirt_with_grass"

minetest.register_biome({
	name = biome_name,
	--node_dust = "",
	node_top = node_top,
	depth_top = 1,
	node_filler = "default:dirt",
	depth_filler = 3,
	--node_stone = "",
	--node_water_top = "",
	--depth_water_top = ,
	--node_water = "",
	--node_river_water = "",
	y_min = 4,
	y_max = 35,
	heat_point = 75,
	humidity_point = 90,
})



--
-- Register ores
--

-- All mapgens except singlenode
-- Blob ore first to avoid other ores inside blobs



--
-- Ferns
--

	-- Big Tree Fern
local n1 = { name = "air", prob = 0 }
local n2 = { name = "australia:tree_fern_leaf_big_end" }
local n3 = { name = "australia:tree_fern_leaf_big" }
local n4 = { name = "australia:fern_trunk_big" }
local n5 = { name = "australia:tree_fern_leaf_big_end", param2 = 1 }
local n6 = { name = "australia:fern_trunk_big_top" }
local n7 = { name = "australia:tree_fern_leaf_big_end", param2 = 3 }
local n8 = { name = "australia:tree_fern_leaves_giant" }
local n9 = { name = "australia:tree_fern_leaf_big_end", param2 = 2 }
minetest.register_decoration({
	deco_type = "schematic",
	sidelen = 80,
	place_on = {"default:dirt_with_grass"},
	y_min = 6,
	y_max = 20,
	fill_ratio = 0.003,
	biomes = {"far_north_queensland"},
	schematic = {
		size = {y = 7, x = 9, z = 9},
	data = {
			n1, n1, n1, n1, n1, n1, n1, n1, n1, n1, n1, n1, n1, n1, n1, n1, n1, 
			n1, n1, n1, n1, n1, n1, n1, n1, n1, n1, n1, n1, n1, n1, n1, n1, n1, 
			n1, n1, n1, n1, n1, n1, n2, n1, n1, n1, n1, n1, n1, n1, n1, n1, n1, 
			n1, n1, n1, n1, n1, n1, n1, n1, n1, n1, n1, n1, n1, n1, n1, n1, n1, 
			n1, n1, n1, n1, n1, n1, n1, n1, n1, n1, n1, n1, n1, n1, n1, n1, n1, 
			n1, n1, n1, n1, n1, n1, n1, n1, n1, n1, n1, n1, n1, n1, n1, n1, n1, 
			n1, n1, n1, n1, n1, n1, n1, n1, n1, n1, n3, n1, n1, n1, n1, n1, n1, 
			n1, n1, n1, n1, n1, n1, n1, n1, n1, n1, n1, n1, n1, n1, n1, n1, n1, 
			n1, n1, n1, n1, n1, n1, n1, n1, n1, n1, n1, n1, n1, n1, n1, n1, n1, 
			n1, n1, n1, n1, n1, n1, n1, n1, n1, n1, n1, n1, n1, n1, n1, n1, n1, 
			n1, n1, n1, n1, n1, n1, n1, n1, n1, n1, n1, n1, n1, n1, n3, n1, n1, 
			n1, n1, n1, n1, n1, n1, n1, n1, n1, n1, n1, n1, n1, n1, n1, n1, n1, 
			n1, n1, n1, n1, n1, n1, n1, n1, n1, n1, n1, n1, n1, n1, n1, n1, n1, 
			n1, n1, n1, n1, n1, n1, n1, n1, n1, n1, n1, n1, n1, n1, n1, n1, n1, 
			n3, n1, n1, n1, n1, n1, n1, n1, n1, n1, n1, n1, n1, n1, n1, n1, n1, 
			n1, n4, n1, n1, n1, n1, n1, n1, n1, n1, n4, n1, n1, n1, n1, n1, n1, 
			n1, n1, n4, n1, n1, n1, n1, n1, n1, n1, n1, n4, n1, n1, n1, n1, n5, 
			n1, n1, n1, n6, n1, n1, n1, n7, n1, n3, n1, n3, n8, n3, n1, n3, n1, 
			n1, n1, n3, n1, n1, n1, n3, n1, n1, n1, n1, n1, n1, n1, n1, n1, n1, 
			n1, n1, n1, n1, n1, n1, n1, n1, n1, n1, n1, n1, n1, n1, n1, n1, n1, 
			n1, n1, n1, n1, n1, n1, n1, n1, n1, n1, n1, n1, n1, n1, n1, n1, n1, 
			n1, n1, n1, n1, n1, n1, n1, n3, n1, n1, n1, n1, n1, n1, n1, n1, n1, 
			n1, n1, n1, n1, n1, n1, n1, n1, n1, n1, n1, n1, n1, n1, n1, n1, n1, 
			n1, n1, n1, n1, n1, n1, n1, n1, n1, n1, n1, n1, n1, n1, n1, n1, n1, 
			n1, n1, n1, n1, n1, n1, n1, n1, n1, n1, n1, n1, n1, n1, n1, n1, n1, 
			n1, n1, n1, n1, n1, n1, n1, n1, n1, n1, n1, n3, n1, n1, n1, n1, n1, 
			n1, n1, n1, n1, n1, n1, n1, n1, n1, n1, n1, n1, n1, n1, n1, n1, n1, 
			n1, n1, n1, n1, n1, n1, n1, n1, n1, n1, n1, n1, n1, n1, n1, n1, n1, 
			n1, n1, n1, n1, n1, n1, n1, n1, n1, n1, n1, n1, n1, n1, n3, n1, n1, 
			n1, n1, n1, n1, n1, n1, n1, n1, n1, n1, n1, n1, n1, n1, n1, n1, n1, 
			n1, n1, n1, n1, n1, n1, n1, n1, n1, n1, n1, n1, n1, n1, n1, n1, n1, 
			n1, n1, n1, n1, n1, n1, n1, n1, n1, n1, n1, n1, n1, n1, n1, n1, n1, 
			n9, n1, n1, n1, n1, n1, n1, n1, n1, n1, n1, n1, n1, n1, n1, n1, n1, 
			n1, n1, n1, n1, n1, n1, 
			},
		yslice_prob = {},
	},
	flags = "place_center_x, place_center_z",
})

	-- Giant Tree Fern
local n1 = { name = "air", prob = 0 }
local n2 = { name = "australia:tree_fern_leaf_big_end" }
local n3 = { name = "australia:tree_fern_leaf_big" }
local n4 = { name = "australia:fern_trunk_big" }
local n5 = { name = "australia:tree_fern_leaf_big_end", param2 = 1 }
local n6 = { name = "australia:fern_trunk_big_top" }
local n7 = { name = "australia:tree_fern_leaf_big_end", param2 = 3 }
local n8 = { name = "australia:tree_fern_leaves_giant" }
local n9 = { name = "australia:tree_fern_leaf_big_end", param2 = 2 }
minetest.register_decoration({
	deco_type = "schematic",
	sidelen = 80,
	place_on = {"default:dirt_with_grass"},
	y_min = 7,
	y_max = 18,
	fill_ratio = 0.005,
	biomes = {"far_north_queensland"},
	schematic = {
		size = {y = 13, x = 9, z = 9},
	data = {
			n1, n1, n1, n1, n1, n1, n1, n1, n1, n1, n1, n1, n1, n1, n1, n1, n1, 
			n1, n1, n1, n1, n1, n1, n1, n1, n1, n1, n1, n1, n1, n1, n1, n1, n1, 
			n1, n1, n1, n1, n1, n1, n1, n1, n1, n1, n1, n1, n1, n1, n1, n1, n1, 
			n1, n1, n1, n1, n1, n1, n1, n1, n1, n1, n1, n1, n1, n1, n1, n1, n1, 
			n1, n1, n1, n1, n1, n1, n1, n1, n1, n1, n1, n1, n1, n1, n1, n1, n1, 
			n1, n1, n1, n1, n1, n1, n1, n1, n1, n2, n1, n1, n1, n1, n1, n1, n1, 
			n1, n1, n1, n1, n1, n1, n1, n1, n1, n1, n1, n1, n1, n1, n1, n1, n1, 
			n1, n1, n1, n1, n1, n1, n1, n1, n1, n1, n1, n1, n1, n1, n1, n1, n1, 
			n1, n1, n1, n1, n1, n1, n1, n1, n1, n1, n1, n1, n1, n1, n1, n1, n1, 
			n1, n1, n1, n1, n1, n1, n1, n1, n1, n1, n1, n1, n1, n1, n1, n1, n1, 
			n1, n1, n1, n1, n1, n1, n1, n1, n1, n1, n1, n1, n1, n1, n1, n1, n1, 
			n1, n1, n1, n1, n1, n1, n1, n1, n1, n1, n1, n1, n1, n1, n1, n1, n1, 
			n1, n1, n1, n1, n1, n1, n1, n1, n1, n1, n1, n1, n1, n1, n1, n1, n3, 
			n1, n1, n1, n1, n1, n1, n1, n1, n1, n1, n1, n1, n1, n1, n1, n1, n1, 
			n1, n1, n1, n1, n1, n1, n1, n1, n1, n1, n1, n1, n1, n1, n1, n1, n1, 
			n1, n1, n1, n1, n1, n1, n1, n1, n1, n1, n1, n1, n1, n1, n1, n1, n1, 
			n1, n1, n1, n1, n1, n1, n1, n1, n1, n1, n1, n1, n1, n1, n1, n1, n1, 
			n1, n1, n1, n1, n1, n1, n1, n1, n1, n1, n1, n1, n1, n1, n1, n1, n1, 
			n1, n1, n1, n1, n1, n1, n1, n1, n1, n1, n1, n1, n1, n1, n1, n1, n1, 
			n1, n1, n1, n1, n1, n1, n1, n1, n1, n1, n1, n1, n1, n1, n1, n1, n1, 
			n1, n1, n1, n1, n1, n1, n3, n1, n1, n1, n1, n1, n1, n1, n1, n1, n1, 
			n1, n1, n1, n1, n1, n1, n1, n1, n1, n1, n1, n1, n1, n1, n1, n1, n1, 
			n1, n1, n1, n1, n1, n1, n1, n1, n1, n1, n1, n1, n1, n1, n1, n1, n1, 
			n1, n1, n1, n1, n1, n1, n1, n1, n1, n1, n1, n1, n1, n1, n1, n1, n1, 
			n1, n1, n1, n1, n1, n1, n1, n1, n1, n1, n1, n1, n1, n1, n1, n1, n1, 
			n1, n1, n1, n1, n1, n1, n1, n1, n1, n1, n1, n1, n1, n1, n1, n1, n1, 
			n1, n1, n1, n1, n1, n1, n1, n1, n1, n1, n1, n1, n3, n1, n1, n1, n1, 
			n1, n1, n1, n1, n1, n1, n1, n1, n1, n1, n1, n1, n1, n4, n1, n1, n1, 
			n1, n1, n1, n1, n1, n4, n1, n1, n1, n1, n1, n1, n1, n1, n4, n1, n1, 
			n1, n1, n1, n1, n1, n1, n4, n1, n1, n1, n1, n1, n1, n1, n1, n4, n1, 
			n1, n1, n1, n1, n1, n1, n1, n4, n1, n1, n1, n1, n1, n1, n1, n1, n4, 
			n1, n1, n1, n1, n1, n1, n1, n1, n4, n1, n1, n1, n1, n1, n1, n1, n1, 
			n4, n1, n1, n1, n1, n1, n1, n1, n1, n4, n1, n1, n1, n1, n5, n1, n1, 
			n1, n6, n1, n1, n1, n7, n1, n3, n1, n3, n8, n3, n1, n3, n1, n1, n1, 
			n3, n1, n1, n1, n3, n1, n1, n1, n1, n1, n1, n1, n1, n1, n1, n1, n1, 
			n1, n1, n1, n1, n1, n1, n1, n1, n1, n1, n1, n1, n1, n1, n1, n1, n1, 
			n1, n1, n1, n1, n1, n1, n1, n1, n1, n1, n1, n1, n1, n1, n1, n1, n1, 
			n1, n1, n1, n1, n1, n1, n1, n1, n1, n1, n1, n1, n1, n1, n1, n1, n1, 
			n1, n1, n1, n1, n1, n1, n1, n1, n1, n1, n1, n1, n1, n1, n1, n1, n1, 
			n1, n1, n1, n1, n1, n1, n1, n1, n1, n1, n1, n1, n1, n1, n1, n1, n1, 
			n1, n1, n1, n1, n1, n1, n1, n1, n3, n1, n1, n1, n1, n1, n1, n1, n1, 
			n1, n1, n1, n1, n1, n1, n1, n1, n1, n1, n1, n1, n1, n1, n1, n1, n1, 
			n1, n1, n1, n1, n1, n1, n1, n1, n1, n1, n1, n1, n1, n1, n1, n1, n1, 
			n1, n1, n1, n1, n1, n1, n1, n1, n1, n1, n1, n1, n1, n1, n1, n1, n1, 
			n1, n1, n1, n1, n1, n1, n1, n1, n1, n1, n1, n1, n1, n1, n1, n1, n1, 
			n1, n1, n1, n1, n1, n1, n1, n1, n1, n1, n1, n1, n1, n1, n1, n1, n1, 
			n1, n1, n1, n1, n1, n1, n1, n1, n1, n1, n1, n1, n1, n1, n1, n1, n1, 
			n1, n1, n1, n1, n1, n1, n1, n1, n1, n1, n1, n1, n1, n1, n1, n3, n1, 
			n1, n1, n1, n1, n1, n1, n1, n1, n1, n1, n1, n1, n1, n1, n1, n1, n1, 
			n1, n1, n1, n1, n1, n1, n1, n1, n1, n1, n1, n1, n1, n1, n1, n1, n1, 
			n1, n1, n1, n1, n1, n1, n1, n1, n1, n1, n1, n1, n1, n1, n1, n1, n1, 
			n1, n1, n1, n1, n1, n1, n1, n1, n1, n1, n1, n1, n1, n1, n1, n1, n1, 
			n1, n1, n1, n1, n1, n1, n1, n1, n1, n1, n1, n1, n1, n1, n1, n1, n1, 
			n1, n1, n1, n1, n1, n1, n1, n1, n1, n1, n1, n1, n1, n1, n1, n1, n1, 
			n1, n1, n1, n1, n3, n1, n1, n1, n1, n1, n1, n1, n1, n1, n1, n1, n1, 
			n1, n1, n1, n1, n1, n1, n1, n1, n1, n1, n1, n1, n1, n1, n1, n1, n1, 
			n1, n1, n1, n1, n1, n1, n1, n1, n1, n1, n1, n1, n1, n1, n1, n1, n1, 
			n1, n1, n1, n1, n1, n1, n1, n1, n1, n1, n1, n1, n1, n1, n1, n1, n1, 
			n1, n1, n1, n1, n1, n1, n1, n1, n1, n1, n1, n1, n1, n1, n1, n1, n1, 
			n1, n1, n1, n1, n1, n1, n1, n1, n1, n1, n1, n1, n1, n1, n1, n1, n1, 
			n1, n1, n1, n1, n1, n1, n1, n1, n1, n1, n9, n1, n1, n1, n1, n1, n1, 
			n1, n1, n1, n1, n1, n1, n1, n1, n1, n1, n1, n1, n1, n1, n1, n1, 
			},
		yslice_prob = {},
	},
	flags = "place_center_x, place_center_z",
})

	-- Small Tree Fern
local f1 = { name = "australia:fern_trunk" }
local f2 = { name = "australia:tree_fern_leaves_02" }
minetest.register_decoration({
	deco_type = "schematic",
	sidelen = 80,
	place_on = {"default:dirt_with_grass"},
	y_min = 6,
	y_max = 21,
	fill_ratio = 0.01,
	biomes = {"far_north_queensland"},
	schematic = {
		size = {y = 4, x = 1, z = 1},
	data = {
			f1, f1, f1, f2, 
			},
		yslice_prob = {},
	},
})



--
-- Decorations
--
	-- Grasses
aus.biome_register_grass_decorations(
	{
		{-0.03,  0.09,  5},
		{-0.015, 0.075, 4},
		{0,      0.06,  3},
		{0.015,  0.045, 2},
		{0.03,   0.03,  1},
	},
	biome_name, node_top, "default:grass_", 5, 35
)

	-- Dry grasses
aus.biome_register_grass_decorations(
	{
		{0.01, 0.05,  5},
		{0.03, 0.03,  4},
	},
	biome_name, node_top, "default:dry_grass_", 22, 35
)


--
-- Ferns
--




--
-- Trees
--

	-- Daintree Stringybark
aus.schematics.daintree_stringybark_tree = {}
local max_r = 7
local ht = 10
local fruit = nil
local limbs = nil
local tree = "australia:daintree_stringybark_tree"
local leaves = "australia:daintree_stringybark_leaves"
for r = 6,max_r do
	local schem = aus.generate_tree_schematic(9, {x=r, y=ht, z=r}, tree, leaves, fruit, limbs)
	table.insert(aus.schematics.daintree_stringybark_tree, schem)
	minetest.register_decoration({
		deco_type = "schematic",
		sidelen = 80,
		place_on = {"default:dirt_with_grass"},
		y_min = 25,
		y_max = 35,
		fill_ratio = (max_r-r+1)/12000,
		biomes = {"far_north_queensland"},
		schematic = schem,
		flags = "place_center_x, place_center_z",
		rotation = "random",
	})
end

	-- Darwin Woollybutt
aus.register_schem_to_biome("darwin_woollybutt_tree", "far_north_queensland", {
	place_on = {"default:dirt_with_grass"},
	y_min = 25,
	y_max = 35,
	fill_ratio = 12000,
})

	-- Australian Fan Palm
aus.schematics.fan_palm_tree = {}
local max_ht = 9
local r = 3
local tree = "australia:fan_palm_tree"
local leaves = "australia:fan_palm_leaves"
for h = 9,max_ht do
	local schem = aus.generate_fanpalm_tree_schematic(h, r, tree, leaves)
	table.insert(aus.schematics.fan_palm_tree, schem)
	minetest.register_decoration({
		deco_type = "schematic",
		sidelen = 80,
		place_on = {"default:dirt_with_grass"},
		fill_ratio = (max_ht-r+1)/300,
		biomes = {"far_north_queensland"},
		y_min = 5,
		y_max = 20,
		schematic = schem,
		flags = "place_center_x, place_center_z",
		rotation = "random",
	})
end

	-- Lemon Eucalyptus
aus.schematics.lemon_eucalyptus_tree = {}
local max_r = 5
local ht = 7
local fruit = nil
local limbs = nil
local tree = "australia:lemon_eucalyptus_tree"
local leaves = "australia:lemon_eucalyptus_leaves"
for r = 4,max_r do
	local schem = aus.generate_tree_schematic(8, {x=r, y=ht, z=r}, tree, leaves, fruit, limbs)
	table.insert(aus.schematics.lemon_eucalyptus_tree, schem)
	minetest.register_decoration({
		deco_type = "schematic",
		sidelen = 80,
		place_on = {"default:dirt_with_grass"},
		y_min = 20,
		y_max = 35,
		fill_ratio = (max_r-r+1)/12000,
		biomes = {"far_north_queensland"},
		schematic = schem,
		flags = "place_center_x, place_center_z",
		rotation = "random",
	})
end

	-- Lilly Pilly
aus.register_schem_to_biome("lilly_pilly_tree", biome_name, {
	place_on = {node_top},
	y_min = 20,
	y_max = 35,
	fill_ratio = 12000,
})

	-- Merbau
aus.schematics.merbau_tree = {}
local max_ht = 12
local r = 8
local tree = "australia:merbau_tree"
local leaves = "australia:merbau_leaves"
for h = 8,max_ht do
	local schem = aus.generate_rainforest_tree_schematic(h, r, tree, leaves)
	table.insert(aus.schematics.merbau_tree, schem)
	minetest.register_decoration({
		deco_type = "schematic",
		sidelen = 80,
		place_on = {"default:dirt_with_grass"},
		fill_ratio = (max_ht-r+1)/6000,
		biomes = {"far_north_queensland"},
		y_min = 6,
		y_max = 25,
		schematic = schem,
		flags = "place_center_x, place_center_z",
		rotation = "random",
	})
end

	-- River Oak
aus.schematics.river_oak_big_tree = {}
local max_r = 5
local ht = 9
local fruit = nil
local limbs = false
local tree = "australia:river_oak_tree"
local leaves = "australia:river_oak_leaves"
for r = 4,max_r do
	local schem = aus.generate_tree_schematic(3, {x=r, y=ht, z=r}, tree, leaves, fruit, limbs)
	table.insert(aus.schematics.river_oak_big_tree, schem)
	minetest.register_decoration({
		deco_type = "schematic",
		sidelen = 80,
		place_on = {"default:dirt_with_grass"},
		y_min = 25,
		y_max = 35,
		fill_ratio = (max_r-r+1)/12000,
		biomes = {"far_north_queensland"},
		schematic = schem,
		flags = "place_center_x, place_center_z",
		rotation = "random",
	})
end

